Workbook

Sheet 📊 Dashboard
B2: BEWERBUNGSTRACKER 2026
B4: FiAE-Praktikum · Köln & Umgebung · Oktober 2026 – April 2027
B6: Gesamt | C6: Beworben | D6: Nachgefragt | E6: Gespräche | F6: Zusagen | G6: Absagen
B7: =COUNTA('Aktive Bewerbungen'!A6:A100) -> 57 | C7: =COUNTIF('Aktive Bewerbungen'!H6:H100,"Beworben") -> 26 | D7: =COUNTIF('Aktive Bewerbungen'!H6:H100,"Nachgefragt") -> 1 | E7: =COUNTIF('Aktive Bewerbungen'!H6:H100,"Vorstellungsgespräch") -> 0 | F7: =COUNTIF('Aktive Bewerbungen'!H6:H100,"Zusage") -> 0 | G7: =COUNTIF('Aktive Bewerbungen'!H6:H100,"Absage") -> 28
B10: VERTEILUNG NACH STANDORT | F10: VERTEILUNG NACH INTERESSE
B11: Standort | C11: Anzahl | D11: Anteil | F11: Interesse | G11: Anzahl | H11: Anteil
B12: Köln | C12: =COUNTIF('Aktive Bewerbungen'!D6:D100,"*Köln*") -> 29 | D12: =IFERROR(C12/$C$7,0) -> 1.1153846 | F12: Sehr gerne | G12: =COUNTIF('Aktive Bewerbungen'!B6:B100,"Sehr gerne") -> 3 | H12: =IFERROR(G12/$C$7,0) -> 0.11538462
B13: Bergisch Gladbach | C13: =COUNTIF('Aktive Bewerbungen'!D6:D100,"*Bergisch Gladbach*") -> 8 | D13: =IFERROR(C13/$C$7,0) -> 0.30769231 | F13: Gerne | G13: =COUNTIF('Aktive Bewerbungen'!B6:B100,"Gerne") -> 7 | H13: =IFERROR(G13/$C$7,0) -> 0.26923077
B14: Rösrath | C14: =COUNTIF('Aktive Bewerbungen'!D6:D100,"*Rösrath*") -> 7 | D14: =IFERROR(C14/$C$7,0) -> 0.26923077 | F14: Ja | G14: =COUNTIF('Aktive Bewerbungen'!B6:B100,"Ja") -> 12 | H14: =IFERROR(G14/$C$7,0) -> 0.46153846
B15: Troisdorf | C15: =COUNTIF('Aktive Bewerbungen'!D6:D100,"*Troisdorf*") -> 3 | D15: =IFERROR(C15/$C$7,0) -> 0.11538462 | F15: Joa | G15: =COUNTIF('Aktive Bewerbungen'!B6:B100,"Joa") -> 9 | H15: =IFERROR(G15/$C$7,0) -> 0.34615385
B16: Siegburg | C16: =COUNTIF('Aktive Bewerbungen'!D6:D100,"*Siegburg*") -> 3 | D16: =IFERROR(C16/$C$7,0) -> 0.11538462 | F16: Eher nicht | G16: =COUNTIF('Aktive Bewerbungen'!B6:B100,"Eher nicht") -> 1 | H16: =IFERROR(G16/$C$7,0) -> 0.038461538
B17: Sonstige | C17: =COUNTA('Aktive Bewerbungen'!D6:D100)-COUNTIF('Aktive Bewerbungen'!D6:D100,"*Köln*")-COUNTIF('Aktive Bewerbungen'!D6:D100,"*Bergisch Gladbach*")-COUNTIF('Aktive Bewerbungen'!D6:D100,"*Rösrath*")-COUNTIF('Aktive Bewerbungen'!D6:D100,"*Troisdorf*")-COUNTIF('Aktive Bewerbungen'!D6:D100,"*Siegburg*") -> 6 | D17: =IFERROR(C17/$C$7,0) -> 0.23076923
B19: AKTIONEN & HINWEISE
B20: 💡 | C20: Status-Spalte: Dropdown nutzen – Farben aktualisieren sich automatisch.
B21: 📅 | C21: Spalte „Nachgefragt" wird gelb, wenn seit Bewerbung >4 Wochen vergangen sind und noch nicht nachgefragt wurde.
B22: 🎯 | C22: Pipeline-Sheet enthält geplante Firmen mit Recherche-Notizen.
B23: 📌 | C23: „Nehmen keine"-Einträge stehen ausgegraut am Ende der Liste.
B25: Letzte Bearbeitung: | C25: 20.05.2026

Sheet Aktive Bewerbungen
A1: AKTIVE BEWERBUNGEN
A2: Stand: 20.05.2026 · Bewerbungen + Status-Tracking
A5: Unternehmen | B5: Interesse | C5: Website | D5: Standort | E5: Adresse | F5: Datum Bewerbung | G5: Nachgefragt | H5: Status | I5: Ergebnis | J5: Kontakt | K5: Notizen
A6: Netempire | B6: Sehr gerne | C6: Jobs – Netempire Software GmbH | D6: Rösrath | E6: Lüghauser Str. 16, 51503 Rösrath | F6: 2026-02-18 | H6: Absage
A7: SCOOP | B7: Gerne | C7: Jobs - SCOOP Software | D7: Köln | E7: Eiler Str. 3P, 51107 Köln | F7: 2026-02-25 | H7: Absage
A8: bevutaIT | B8: Sehr gerne | C8: Unser Team rund um Köln und überall auf der Welt | bevuta IT | D8: Köln | E8: Ettore-Bugatti-Straße 35, 51149 Köln | F8: 2026-02-25 | H8: Absage
A9: mobivention | B9: Gerne | C9: IT-Dienstleister für App Entwicklung, Web Apps & Backends | D9: Köln | E9: Am bhf 132, 51147 Köln | F9: 2026-02-25 | G9: 2026-04-15 | H9: Nachgefragt
A10: MaProTa Gmbh | B10: Sehr gerne | C10: Karriere - MaProTa GmbH | D10: Rösrath | E10: Lüghauser Str. 16, 51503 Rösrath | F10: 2026-03-11 | H10: Beworben | J10: 02205-9189170
A11: BEWOTEC | B11: Ja | C11: BEWOTEC Karriere – Jobs & Chancen in der Touristiksoftware | D11: Rösrath | E11: Karl-Schiller-Straße 3, 51503 Rösrath | F11: 2026-03-11 | G11: 2026-04-15 | H11: Absage
A12: ISIFIVE eG | B12: Ja | C12: Team - ISIFIVE | D12: Köln | E12: Rösrather Str. 702, 51107 Köln | F12: 2026-03-11 | G12: 2026-04-15 | H12: Absage
A13: PRODATEC | B13: Ja | C13: https://www.prodatec.de/karriere | D13: Bergisch Gladbach | E13: Burggraben 7, 51429 Bergisch Gladbach | F13: 2026-03-11 | G13: 2026-04-15 | H13: Absage
A14: INNEO | B14: Gerne | C14: https://jobs.inneo.com/stellenangebote.html | D14: Köln | E14: Hansestraße 87, 51149 Köln | F14: 2026-03-11 | H14: Absage
A15: REWE Digital | B15: Gerne | C15: https://www.rewe-digital.com/de/jobs?location=K%C3%B6ln%2C%20Deutschland&range=25&sort=distance&city[]=K%C3%B6ln&page=1 | D15: Köln | E15: Humboldtstraße 140-144, 51149 Köln | F15: 2026-03-11 | G15: 2026-04-15 | H15: Absage
A16: CLOUSALE | B16: Joa | C16: ClouSale: Jobs | D16: Rösrath | E16: Hauptstraße 65-67, 51503 Rösrath | F16: 2026-03-25 | H16: Absage
A17: Ditcon GmbH | B17: Joa | C17: https://www.ditcon.de/ | D17: Köln | E17: Fuggerstraße 26, 51149 Köln | F17: 2026-04-01 | H17: Beworben | J17: FISI 02203 89860
A18: Netrix IT works | B18: Gerne | C18: https://www.netrix-it.de/karriere/ | D18: Köln | E18: Hansestraße 97, 51149 Köln | F18: 2026-04-01 | H18: Beworben | J18: FISI
A19: incs | B19: Joa | C19: https://www.incs.org/ueber-uns/ | D19: Köln | E19: Edmund-Rumpler-Straße 6A, 51149 Köln | F19: 2026-04-01 | H19: Absage
A20: ableX GmbH | B20: Joa | C20: Q&A | ableX Data Solutions | D20: Rösrath | E20: Karl-Schiller-Str. 1, 51503 Rösrath | F20: 2026-04-01 | H20: Beworben | J20: 02205-9499950
A21: CGI | B21: Ja | C21: Frequently Asked Questions (FAQ) | CGI.com | D21: Köln | E21: Ettore-Bugatti-Straße 6-14, 51149 Köln | F21: 2026-04-01 | H21: Absage
A22: DerGrünePunkt | B22: Gerne | C22: Karriere | Grüner Punkt | D22: Köln | E22: Edmund-Rumpler-Straße 7, 51149 Köln | F22: 2026-04-01 | H22: Absage
A23: It intouch | B23: Joa | C23: Karriere - Jobs als Mobile Developer bei IT intouch | D23: Bergisch Gladbach | E23: Lustheide 85, 51427 Bergisch Gladbach | F23: 2026-04-15 | H23: Absage
A24: ED Computer & Design GmbH & Co. KG | B24: Joa | C24: https://www.edcud.de/systemhaus-dienstleistungen | D24: Köln | E24: Lina-Bommer-Weg 4, 51149 Köln | F24: 2026-04-15 | H24: Absage
A25: CBS University of Applied Sciences | B25: Ja | C25: https://www.cbs.de/ueber-uns/karriere-an-der-cbs/ausbildung-traineeship#traineeship | D25: Köln-Rodenkirchen | E25: Bahnstraße 6-8 50996 Köln | F25: 2026-04-15 | H25: Absage
A26: CONVOTIS | B26: Ja | C26: https://www.convotis.com/karriere/ | D26: Bergisch Gladbach | E26: Heinz-Fröling-Straße 15 | F26: 2026-04-22 | H26: Absage
A27: HEES | B27: Ja | C27: https://hees.de/karriere/initiativbewerbung/ | D27: Lohmar | E27: Hauptstraße 1b, 53797 Lohmar | F27: 2026-04-22 | H27: Absage
A28: Loco-Soft | B28: Ja | C28: https://loco-soft.de/kontakt | D28: Lindlar | E28: Schlosserstraße 33 | D-51789 Lindlar | F28: 2026-04-22 | H28: Beworben
A29: WARETRACKS | C29: https://www.waretracks.com/ | D29: Köln | E29: August-Horch-Straße 17, 51149 Köln | F29: 2026-04-22 | H29: Beworben
A30: Novum-RGI | B30: Gerne | C30: https://www.novum-rgi.com/contacts/ | D30: Köln | E30: Durchhäuserhof 65, 51107 Köln | F30: 2026-04-29 | H30: Beworben
A31: genDis solution | B31: Joa | C31: https://www.gendis.de/ | D31: Bergisch Gladbach | E31: Schloßstraße 20, 51429 Bergisch Gladbach | F31: 2026-04-29 | H31: Beworben | J31: Gibt es vermutlich nicht mehr
A32: Praxcon | B32: Ja | C32: https://www.praxcon.de/ | D32: Bergisch Gladbach | E32: Schau Ins Land 13, 51429 Bergisch Gladbach | F32: 2026-04-29 | H32: Beworben
A33: kompaktwerk GmbH | B33: Eher nicht | C33: https://www.kompaktwerk.de/wir-sind-kompaktwerk/ | D33: Bergisch Gladbach | E33: Sattlerweg 12 b, 51429 Bergisch Gladbach | F33: 2026-04-29 | H33: Beworben
A34: TecAlliance | B34: Ja | C34: https://career.tecalliance.net/jobs?split_view=true&query=&location=Cologne | D34: Köln | E34: Edmund-Rumpler-Straße 5, 51149 Köln | F34: 2026-04-29 | H34: Beworben
A35: Atos | B35: Ja | C35: https://atos.net/de/join-us?city=118&country=DE | D35: Köln | E35: Von-der-Wettern-Straße 27, 51149 Köln | F35: 2026-04-29 | H35: Beworben
A36: Eulen-IT | B36: Joa | C36: https://www.eulen-it.de/karriere#dataItem-lkmqqnjt | D36: Untereschbach | E36: Brodhausen 1, 51491 Overath | F36: 2026-04-29 | H36: Absage | J36: bewerbung@eulen-it.de
A37: Syntriq GmbH | C37: https://syntriq.de/karriere | D37: Köln | E37: Frankfurter Str. 720/726, 51145 Köln | F37: 2026-04-29 | H37: Beworben
A38: COPA-DATA | C38: https://www.copadata.com/de/karriere/ | D38: Köln | E38: Von-der-Wettern-Straße 27, 51149 Köln | F38: 2026-04-29 | H38: Absage | J38: jobs-cdde@copadata.com
A39: InTradeSys GmbH | C39: https://www.intradesys.com/jobs | D39: Köln | E39: Dillenburger Str. 75, 51105 Köln | F39: 2026-04-29 | H39: Beworben
A40: menten GmbH | C40: https://stellenportal.menten.com/de | D40: Bergisch Gladbach | E40: An d. Gohrsmühle 25, 51465 Bergisch Gladbach | F40: 2026-04-29 | H40: Absage
A41: AB-Informatik GmbH, IT-Systemhaus Siegburg | C41: https://www.ab-informatik.net/ | D41: Siegburg | E41: Am Turm 26, 53721 Siegburg | F41: 2026-04-29 | H41: Beworben
A42: IT-Center Engels | C42: https://www.itc-engels.de/impressum | D42: Troisdorf | E42: Heidegraben 4a, 53842 Troisdorf | F42: 2026-04-29 | H42: Beworben
...

Sheet Pipeline
A1: PIPELINE · GEPLANTE BEWERBUNGEN
A2: Recherche-Liste · Interesse einschätzen und Status auf „Beworben" setzen, dann in „Aktive Bewerbungen" verschieben
A5: Unternehmen | B5: Adresse | C5: Interesse | D5: Status | E5: Bewerbung bis | F5: Notizen / Recherche
A6: lise GmbH | B6: Butzweilerhof-Allee 2 50829 Köln-Ossendorf | D6: Neu | F6: Individuelle Softwareentwicklung, über 100 Mitarbeitende, 5× „Great Place to Work" ausgezeichnet (zuletzt 2026 Platz 8) | .NET, SharePoint, DevOps, KI – IHK-Ausbildungsbetrieb seit 2013
A7: ifaktor GmbH | B7: Bonner Str. 324 50968 Köln-Bayenthal | D7: Neu | F7: IT-Systemhaus seit über 25 Jahren, Fokus KMU, zertifizierter IHK-Ausbildungsbetrieb | ERP/xRM (MS Dynamics), DMS, Cloud, IT-Sicherheit
A8: Webrunners GmbH | B8: Von-Werth-Str. 37 50670 Köln-Innenstadt | D8: Neu | F8: Agentur für individuelle Softwareentwicklung & Webanwendungen, ca. 15 Jahre am Markt | Django/Python, TYPO3, ERP-Schnittstellen – Praktika in Webentwicklung möglich
A9: elancer-team GmbH | B9: Widdersdorfer Str. 188 50825 Köln-Ehrenfeld | D9: Neu | F9: Webagentur, 11–50 Mitarbeitende, klassische Agenturstruktur | WordPress, Ruby on Rails, Individualsoftware, App-Entwicklung
A10: milkycode GmbH | B10: Osterather Str. 7 50739 Köln-Longerich | D10: Neu | F10: Internetagentur mit Fokus auf E-Commerce-Lösungen für den Mittelstand | Magento, Shopware, WooCommerce, PHP/Laravel/Symfony/VueJS
A11: Explicatis GmbH | B11: Max-Planck-Str. 6–8 50858 Köln-Junkersdorf | D11: Neu | F11: Softwareentwicklung & IT-Beratung, dreimal Deloitte „Technology Fast50 Award", eigene Produkte (z. B. Custable) | IoT-Plattformen, Cloud-Native, Mobile Apps – Praktika in Web/Mobile
A12: REWE digital GmbH | B12: Humboldtstr. 140–144 51149 Köln-Porz | D12: Neu | F12: IT-Tochter der REWE Group, einer der größten IT-Arbeitgeber im deutschen Handel | Java, Kotlin, Python, Spring, Angular, Kafka – jährliche FiAe-Ausbildung
A13: business//acts GmbH | B13: Schanzenstr. 7a 51063 Köln-Mülheim | D13: Neu | F13: CRM-/ECM-Softwarehersteller, eigenes Produkt „sellify", ca. 20 Mitarbeitende | CRM-Entwicklung, ECM – Initiativbewerbung für Praktikum empfohlen
A14: Werusys GmbH & Co. KG | B14: Kaiser-Wilhelm-Ring 40 50672 Köln (Amtssitz: Morsestr. 4, 50769 Köln) | D14: Neu | F14: IT-Dienstleister für Prozessindustrie, Teil der Amitec-Gruppe | MES, Energiemanagement, AVEVA PI, eigenes Produkt SynergyVision MES
A15: Saticon GmbH | B15: Köln (Innenstadt) | D15: Neu | F15: Webagentur mit Fokus auf Softwareentwicklung und Online-Marketing | Webentwicklung, Webanwendungen, SEO
A16: Devside GmbH | B16: Köln (HRB 94897) | D16: Neu | F16: Prozessorientierter Softwareentwickler und App-Dienstleister | Softwareentwicklung, App-Entwicklung
A17: inch-media GmbH | B17: Braunsberger Feld 12 51429 Bergisch Gladbach-Herkenrath | D17: Neu | F17: IT-Systemhaus und Webagentur für KMU, 5–9 Mitarbeitende | Webentwicklung, IT-Security – Praktika via Initiativbewerbung
... A26: Pronova BKK | B26: Horst-Henning-Platz 1 51373 Leverkusen | D26: Neu | F26: Gesetzliche Krankenkasse mit eigener Softwareentwicklung | Versicherungssoftware – FiAe-Ausbildung ab 01.08.2026
